<?xml version="1.0"?>
<robot name="braccio">

<link name="base_link">
  <visual>
    <geometry>
      <cylinder length="0.075" radius="0.075"/>
    </geometry>
    
    <material name="silver">
    	<color rgba="0.75 0.75 0.75 1"/>
    </material>
    
    <origin rpy="0 0 0" xyz="0 0 0.0375"/>
  </visual>

  <collision>
    <geometry>
      <cylinder length="0.075" radius="0.075"/>
    </geometry>

    <origin rpy="0 0 0" xyz="0 0 0.0375"/>
  </collision>

  <inertial>
    <mass value="0.3"/>
    <origin rpy="0 0 0" xyz="0 0 0.0375"/>
    <inertia ixx="0.000563" iyy="0.000563" izz="0.00047" ixy="0" ixz="0" iyz="0"/>
  </inertial>
</link>

<link name="link_1">
  <visual>
    <geometry>
      <box size="0.08 0.035 0.025"/>
    </geometry>
  
    <material name="silver2">
      <color rgba="0.8 0.6 0.75 1"/>
    </material>
  
    <origin rpy="0 0 0" xyz="0.0 0 0.0125"/>
  </visual>

  <collision>
    <geometry>
      <box size="0.08 0.035 0.025"/>
    </geometry>

    <origin rpy="0 0 0" xyz="0.0 0 0.0125"/>
  </collision>

  <inertial>
    <mass value="0.059"/>
    <origin rpy="0 0 0" xyz="0 0 0.0125"/>
    <inertia ixx="0.00001074" iyy="0.000027165" izz="0.00003176" ixy="0" ixz="0" iyz="0"/>
  </inertial>
</link>

<joint name="joint_1" type="revolute">
  <axis xyz="0 0 1"/>
  <limit
      lower="-300.14"
      upper="300.14"
      effort="370"
      velocity="1.26" />
  <parent link="base_link"/>
  <child link="link_1"/>
  <origin rpy="0 0 0" xyz="0.0 0.0 0.085"/>
</joint>

<transmission name="tran1">
  <type>transmission_interface/SimpleTransmission</type>
  <joint name="joint_1">
    <hardwareInterface>hardware_interface/PositionJointInterface</hardwareInterface>
   <!-- <hardwareInterface>VelocityJointInterface</hardwareInterface>  -->
  </joint>
  <actuator name="motor1">
    <hardwareInterface>hardware_interface/PositionJointInterface</hardwareInterface>
   <!-- <hardwareInterface>VelocityJointInterface</hardwareInterface>  -->
    <mechanicalReduction>1</mechanicalReduction>
  </actuator>
</transmission>


<gazebo>
  <plugin name="ros_control" filename="libgazebo_ros_control.so">
<!--    <robotNamespace>/braccio</robotNamespace> -->
  </plugin>
</gazebo>

<!--
<gazebo>
      <plugin name="ros_control" filename="libhwi_switch_gazebo_ros_control.so">
        <robotNamespace>braccio</robotNamespace> 
        <filterJointsParam>joint_names</filterJointsParam> 
      </plugin>
    </gazebo>
 -->
</robot>
